\Lib\site-packages\torch\utils\data\dataloader.py", line 1145, in _try_get_data
    raise RuntimeError('DataLoader worker (pid(s) {}) exited unexpectedly'.format(pids_str)) from e
RuntimeError: DataLoader worker (pid(s) 11384, 3188) exited unexpectedly
